Workbook

Sheet Sheet1
A1: Provider | B1: Count
A2: Backblaze | B2: 3
A3: Cloudflare | B3: 8
A4: Duolingo | B4: 3
A5: Eight Sleep | B5: 1
A6: Garmin | B6: 2
A7: Google | B7: 1
A8: Letterboxd | B8: 1
A9: Netflix | B9: 1
A10: NYT Games | B10: 1
A11: Oura | B11: 1
A12: Pocket Casts | B12: 1
A13: Spotify | B13: 1
... A27: Statsig | B27: 1

Sheet FINAL DATASET (2)
A1: Name of Provider | B1: Bar Chart (H) | C1: Bubble Map | D1: Column Chart (V) | E1: Choropleth Map | F1: Grouped Bar Chart | G1: Icon Array | H1: Line Chart | I1: Multi-Series Line Chart | J1: Numeric | K1: Pie Chart | L1: Ranked List | M1: Stacked Area Chart | N1: Table | O1: Timeline | P1: Tree Map | Q1: Stacked Bar Chart | R1: Stack Prop. Bar Chart | S1: Map | T1: Donut Chart | U1: Radial Chart | V1: Dumbell Chart | W1: Sankey Diagram | X1: Dot Plot
A2: Backblaze | D2: X | H2: X | J2: X | K2: X | N2: X | Y2: =COUNTIF(B2:X2,"=X") -> 5 | Z2: =COUNTIF(B2:X2,"=X")/23 -> 0.2173913
A3: Cloudflare | B3: X | C3: X | E3: X | H3: X | I3: X | J3: X | L3: X | M3: X | N3: X | P3: X | Q3: X | X3: X | Y3: =COUNTIF(B3:X3,"=X") -> 12 | Z3: =COUNTIF(B3:X3,"=X")/23 -> 0.52173913
A4: Duolingo | E4: X | J4: X | L4: X | N4: X | Y4: =COUNTIF(B4:X4,"=X") -> 4 | Z4: =COUNTIF(B4:X4,"=X")/23 -> 0.17391304
A5: Eight Sleep | D5: X | J5: X | L5: X | N5: X | Y5: =COUNTIF(B5:X5,"=X") -> 4 | Z5: =COUNTIF(B5:X5,"=X")/23 -> 0.17391304
A6: Garmin | D6: X | F6: X | I6: X | J6: X | Y6: =COUNTIF(B6:X6,"=X") -> 4 | Z6: =COUNTIF(B6:X6,"=X")/23 -> 0.17391304
A7: Google | L7: X | Y7: =COUNTIF(B7:X7,"=X") -> 1 | Z7: =COUNTIF(B7:X7,"=X")/23 -> 0.043478261
A8: Letterboxd | J8: X | L8: X | Y8: =COUNTIF(B8:X8,"=X") -> 2 | Z8: =COUNTIF(B8:X8,"=X")/23 -> 0.086956522
A9: Netflix | D9: X | J9: X | Y9: =COUNTIF(B9:X9,"=X") -> 2 | Z9: =COUNTIF(B9:X9,"=X")/23 -> 0.086956522
A10: NYT Games | D10: X | J10: X | L10: X | Y10: =COUNTIF(B10:X10,"=X") -> 3 | Z10: =COUNTIF(B10:X10,"=X")/23 -> 0.13043478
A11: Oura | B11: X | J11: X | L11: X | N11: X | Y11: =COUNTIF(B11:X11,"=X") -> 4 | Z11: =COUNTIF(B11:X11,"=X")/23 -> 0.17391304
A12: Pocket Casts | J12: X | L12: X | N12: X | Y12: =COUNTIF(B12:X12,"=X") -> 3 | Z12: =COUNTIF(B12:X12,"=X")/23 -> 0.13043478
A13: Spotify | J13: X | L13: X | Y13: =COUNTIF(B13:X13,"=X") -> 2 | Z13: =COUNTIF(B13:X13,"=X")/23 -> 0.086956522
A14: Strava | J14: X | Y14: =COUNTIF(B14:X14,"=X") -> 1 | Z14: =COUNTIF(B14:X14,"=X")/23 -> 0.043478261
A15: Tinder | J15: X | Y15: =COUNTIF(B15:X15,"=X") -> 1 | Z15: =COUNTIF(B15:X15,"=X")/23 -> 0.043478261
A16: Tiktok | J16: X | L16: X | Y16: =COUNTIF(B16:X16,"=X") -> 2 | Z16: =COUNTIF(B16:X16,"=X")/23 -> 0.086956522
A17: UDisc | J17: X | Y17: =COUNTIF(B17:X17,"=X") -> 1 | Z17: =COUNTIF(B17:X17,"=X")/23 -> 0.043478261
A18: Wikipedia | G18: X | J18: X | O18: X | Y18: =COUNTIF(B18:X18,"=X") -> 3 | Z18: =COUNTIF(B18:X18,"=X")/23 -> 0.13043478
A19: Youtube | J19: X | L19: X | Y19: =COUNTIF(B19:X19,"=X") -> 2 | Z19: =COUNTIF(B19:X19,"=X")/23 -> 0.086956522
A20: Dead By Daylight | J20: X | Y20: =COUNTIF(B20:X20,"=X") -> 1 | Z20: =COUNTIF(B20:X20,"=X")/23 -> 0.043478261
A21: eBird | E21: X | H21: X | J21: X | L21: X | S21: X | Y21: =COUNTIF(B21:X21,"=X") -> 5 | Z21: =COUNTIF(B21:X21,"=X")/23 -> 0.2173913
A22: Chess | J22: X | L22: X | N22: X | Y22: =COUNTIF(B22:X22,"=X") -> 3 | Z22: =COUNTIF(B22:X22,"=X")/23 -> 0.13043478
A23: Games Industry | L23: X | N23: X | T23: X | Y23: =COUNTIF(B23:X23,"=X") -> 3 | Z23: =COUNTIF(B23:X23,"=X")/23 -> 0.13043478
A24: Epic Games | G24: X | J24: X | L24: X | U24: X | Y24: =COUNTIF(B24:X24,"=X") -> 4 | Z24: =COUNTIF(B24:X24,"=X")/23 -> 0.17391304
A25: Collector Daily | J25: X | N25: X | Y25: =COUNTIF(B25:X25,"=X") -> 2 | Z25: =COUNTIF(B25:X25,"=X")/23 -> 0.086956522
A26: Stack Overflow | B26: X | J26: X | N26: X | R26: X | V26: X | W26: X | Y26: =COUNTIF(B26:X26,"=X") -> 6 | Z26: =COUNTIF(B26:X26,"=X")/23 -> 0.26086957
A27: Statsig | B27: X | F27: X | J27: X | Y27: =COUNTIF(B27:X27,"=X") -> 3 | Z27: =COUNTIF(B27:X27,"=X")/23 -> 0.13043478
B28: =COUNTIF(B2:B27,"=X") -> 4 | C28: =COUNTIF(C2:C27,"=X") -> 1 | D28: =COUNTIF(D2:D27,"=X") -> 5 | E28: =COUNTIF(E2:E27,"=X") -> 3 | F28: =COUNTIF(F2:F27,"=X") -> 2 | G28: =COUNTIF(G2:G27,"=X") -> 2 | H28: =COUNTIF(H2:H27,"=X") -> 3 | I28: =COUNTIF(I2:I27,"=X") -> 2 | ... X28: =COUNTIF(X2:X27,"=X") -> 1
B29: =COUNTIF(B2:B27,"=X")/26 -> 0.15384615 | C29: =COUNTIF(C2:C27,"=X")/26 -> 0.038461538 | D29: =COUNTIF(D2:D27,"=X")/26 -> 0.19230769 | E29: =COUNTIF(E2:E27,"=X")/26 -> 0.11538462 | F29: =COUNTIF(F2:F27,"=X")/26 -> 0.076923077 | G29: =COUNTIF(G2:G27,"=X")/26 -> 0.076923077 | H29: =COUNTIF(H2:H27,"=X")/26 -> 0.11538462 | I29: =COUNTIF(I2:I27,"=X")/26 -> 0.076923077 | ... X29: =COUNTIF(X2:X27,"=X")/26 -> 0.038461538
A33: Name of Provider | B33: Area | C33: Bar | D33: Circle | E33: Diagram | F33: Distribution | G33: Grid & Matrix | H33: Line | I33: Map | J33: Point | K33: Table | L33: Text | M33: Trees & Networks
A34: Backblaze | B34: =IF(COUNTA(M2)>0,"X","") | C34: =IF(COUNTA(C2,E2,G2,R2,S2,V2)>0,"X","") | D34: =IF(COUNTA(K2,T2)>0,"X","") -> X | E34: =IF(COUNTA(O2,W2)>0,"X","") | F34: =IF(COUNTA(G2)>0,"X","") | H34: =IF(COUNTA(H2,I2)>0,"X","") -> X | I34: =IF(COUNTA(E2,S2)>0,"X","") | J34: =IF(COUNTA(C2,V2,X2)>0,"X","") | K34: =IF(COUNTA(N2,L2,J2)>0,"X","") -> X | M34: =IF(COUNTA(P2)>0,"X","") | N34: =COUNTIF(B34:M34,"=X") -> 3 | O34: =COUNTIF(B34:M34,"=X")/12 -> 0.25 | Q34: Based on visualization taxonomy:
A35: Cloudflare | B35: =IF(COUNTA(M3)>0,"X","") -> X | C35: =IF(COUNTA(C3,E3,G3,R3,S3,V3)>0,"X","") -> X | D35: =IF(COUNTA(D3,F3,H3,S3,T3,W3)>0,"X","") -> X | E35: =IF(COUNTA(O3,W3)>0,"X","") | F35: =IF(COUNTA(G3)>0,"X","") | H35: =IF(COUNTA(H3,I3)>0,"X","") -> X | I35: =IF(COUNTA(E3,S3)>0,"X","") -> X | J35: =IF(COUNTA(C3,V3,X3)>0,"X","") -> X | K35: =IF(COUNTA(N3,L3,J3)>0,"X","") -> X | M35: =IF(COUNTA(P3)>0,"X","") -> X | N35: =COUNTIF(B35:M35,"=X") -> 8 | O35: =COUNTIF(B35:M35,"=X")/12 -> 0.66666667 | Q35: http://olivalab.mit.edu/Papers/Borkin_etal_MemorableVisualization_TVCG2013.pdf
A36: Duolingo | B36: =IF(COUNTA(M4)>0,"X","") | C36: =IF(COUNTA(C4,E4,G4,R4,S4,V4)>0,"X","") -> X | D36: =IF(COUNTA(K4,T4)>0,"X","") | E36: =IF(COUNTA(O4,W4)>0,"X","") | F36: =IF(COUNTA(G4)>0,"X","") | H36: =IF(COUNTA(H4,I4)>0,"X","") | I36: =IF(COUNTA(E4,S4)>0,"X","") -> X | J36: =IF(COUNTA(C4,V4,X4)>0,"X","") | K36: =IF(COUNTA(N4,L4,J4)>0,"X","") -> X | M36: =IF(COUNTA(P4)>0,"X","") | N36: =COUNTIF(B36:M36,"=X") -> 3 | O36: =COUNTIF(B36:M36,"=X")/12 -> 0.25
A37: Eight Sleep | B37: =IF(COUNTA(M5)>0,"X","") | C37: =IF(COUNTA(C5,E5,G5,R5,S5,V5)>0,"X","") | D37: =IF(COUNTA(K5,T5)>0,"X","") | E37: =IF(COUNTA(O5,W5)>0,"X","") | F37: =IF(COUNTA(G5)>0,"X","") | H37: =IF(COUNTA(H5,I5)>0,"X","") | I37: =IF(COUNTA(E5,S5)>0,"X","") | J37: =IF(COUNTA(C5,V5,X5)>0,"X","") | K37: =IF(COUNTA(N5,L5,J5)>0,"X","") -> X | M37: =IF(COUNTA(P5)>0,"X","") | N37: =COUNTIF(B37:M37,"=X") -> 1 | O37: =COUNTIF(B37:M37,"=X")/12 -> 0.083333333 | Q37: {=TRANSPOSE(B33:M33)} -> Area | R37: Stacked Area Chart
A38: Garmin | B38: =IF(COUNTA(M6)>0,"X","") | C38: =IF(COUNTA(C6,E6,G6,R6,S6,V6)>0,"X","") | D38: =IF(COUNTA(K6,T6)>0,"X","") | E38: =IF(COUNTA(O6,W6)>0,"X","") | F38: =IF(COUNTA(G6)>0,"X","") | H38: =IF(COUNTA(H6,I6)>0,"X","") -> X | I38: =IF(COUNTA(E6,S6)>0,"X","") | J38: =IF(COUNTA(C6,V6,X6)>0,"X","") | K38: =IF(COUNTA(N6,L6,J6)>0,"X","") -> X | M38: =IF(COUNTA(P6)>0,"X","") | N38: =COUNTIF(B38:M38,"=X") -> 2 | O38: =COUNTIF(B38:M38,"=X")/12 -> 0.16666667 | Q38: Bar | R38: Bar Chart (H) | S38: Column Chart (V) | T38: Grouped Bar Chart | U38: Stacked Bar Chart | V38: Stacked Prop. Bar Chart | W38: Radial Chart
A39: Google | B39: =IF(COUNTA(M7)>0,"X","") | C39: =IF(COUNTA(C7,E7,G7,R7,S7,V7)>0,"X","") | D39: =IF(COUNTA(K7,T7)>0,"X","") | E39: =IF(COUNTA(O7,W7)>0,"X","") | F39: =IF(COUNTA(G7)>0,"X","") | H39: =IF(COUNTA(H7,I7)>0,"X","") | I39: =IF(COUNTA(E7,S7)>0,"X","") | J39: =IF(COUNTA(C7,V7,X7)>0,"X","") | K39: =IF(COUNTA(N7,L7,J7)>0,"X","") -> X | M39: =IF(COUNTA(P7)>0,"X","") | N39: =COUNTIF(B39:M39,"=X") -> 1 | O39: =COUNTIF(B39:M39,"=X")/12 -> 0.083333333 | Q39: Circle | R39: Pie Chart | S39: Donut Chart
A40: Letterboxd | B40: =IF(COUNTA(M8)>0,"X","") | C40: =IF(COUNTA(C8,E8,G8,R8,S8,V8)>0,"X","") | D40: =IF(COUNTA(K8,T8)>0,"X","") | E40: =IF(COUNTA(O8,W8)>0,"X","") | F40: =IF(COUNTA(G8)>0,"X","") | H40: =IF(COUNTA(H8,I8)>0,"X","") | I40: =IF(COUNTA(E8,S8)>0,"X","") | J40: =IF(COUNTA(C8,V8,X8)>0,"X","") | K40: =IF(COUNTA(N8,L8,J8)>0,"X","") -> X | M40: =IF(COUNTA(P8)>0,"X","") | N40: =COUNTIF(B40:M40,"=X") -> 1 | O40: =COUNTIF(B40:M40,"=X")/12 -> 0.083333333 | Q40: Diagram | R40: Timeline | S40: Sankey Diagram
A41: Netflix | B41: =IF(COUNTA(M9)>0,"X","") | C41: =IF(COUNTA(C9,E9,G9,R9,S9,V9)>0,"X","") | D41: =IF(COUNTA(K9,T9)>0,"X","") | E41: =IF(COUNTA(O9,W9)>0,"X","") | F41: =IF(COUNTA(G9)>0,"X","") | H41: =IF(COUNTA(H9,I9)>0,"X","") | I41: =IF(COUNTA(E9,S9)>0,"X","") | J41: =IF(COUNTA(C9,V9,X9)>0,"X","") | K41: =IF(COUNTA(N9,L9,J9)>0,"X","") -> X | M41: =IF(COUNTA(P9)>0,"X","") | N41: =COUNTIF(B41:M41,"=X") -> 1 | O41: =COUNTIF(B41:M41,"=X")/12 -> 0.083333333 | Q41: Distribution | R41: Icon Array
A42: NYT Games | B42: =IF(COUNTA(M10)>0,"X","") | C42: =IF(COUNTA(C10,E10,G10,R10,S10,V10)>0,"X","") | D42: =IF(COUNTA(K10,T10)>0,"X","") | E42: =IF(COUNTA(O10,W10)>0,"X","") | F42: =IF(COUNTA(G10)>0,"X","") | H42: =IF(COUNTA(H10,I10)>0,"X","") | I42: =IF(COUNTA(E10,S10)>0,"X","") | J42: =IF(COUNTA(C10,V10,X10)>0,"X","") | K42: =IF(COUNTA(N10,L10,J10)>0,"X","") -> X | M42: =IF(COUNTA(P10)>0,"X","") | N42: =COUNTIF(B42:M42,"=X") -> 1 | O42: =COUNTIF(B42:M42,"=X")/12 -> 0.083333333 | Q42: Grid & Matrix
A43: Oura | B43: =IF(COUNTA(M11)>0,"X","") | C43: =IF(COUNTA(C11,E11,G11,R11,S11,V11)>0,"X","") | D43: =IF(COUNTA(K11,T11)>0,"X","") | E43: =IF(COUNTA(O11,W11)>0,"X","") | F43: =IF(COUNTA(G11)>0,"X","") | H43: =IF(COUNTA(H11,I11)>0,"X","") | I43: =IF(COUNTA(E11,S11)>0,"X","") | J43: =IF(COUNTA(C11,V11,X11)>0,"X","") | K43: =IF(COUNTA(N11,L11,J11)>0,"X","") -> X | M43: =IF(COUNTA(P11)>0,"X","") | N43: =COUNTIF(B43:M43,"=X") -> 1 | O43: =COUNTIF(B43:M43,"=X")/12 -> 0.083333333 | Q43: Line | R43: Line Chart | S43: Multi-Series Line Chart
...

Sheet FINAL DATASET
A1: Name of Provider | B1: Bar Chart (H) | C1: Bubble Map | D1: Column Chart (V) | E1: Choropleth Map | F1: Grouped Bar Chart | G1: Icon Array | H1: Line Chart | I1: Multi-Series Line Chart | J1: Numeric | K1: Pie Chart | L1: Ranked List | M1: Stacked Area Chart | N1: Table | O1: Timeline | P1: Tree Map | Q1: Stacked Bar Chart | R1: Stack Prop. Bar Chart | S1: Map | T1: Donut Chart | U1: Radial Chart | V1: Dumbell Chart | W1: Sankey Diagram | X1: Dot Plot
A2: Backblaze | D2: X | H2: X | J2: X | K2: X | N2: X | Y2: =COUNTIF(B2:X2,"=X") -> 5 | Z2: =COUNTIF(B2:X2,"=X")/23 -> 0.2173913
A3: Cloudflare | B3: X | C3: X | E3: X | H3: X | I3: X | J3: X | L3: X | M3: X | N3: X | P3: X | Q3: X | X3: X | Y3: =COUNTIF(B3:X3,"=X") -> 12 | Z3: =COUNTIF(B3:X3,"=X")/23 -> 0.52173913
A4: Duolingo | E4: X | J4: X | L4: X | N4: X | Y4: =COUNTIF(B4:X4,"=X") -> 4 | Z4: =COUNTIF(B4:X4,"=X")/23 -> 0.17391304
A5: Eight Sleep | D5: X | J5: X | L5: X | N5: X | Y5: =COUNTIF(B5:X5,"=X") -> 4 | Z5: =COUNTIF(B5:X5,"=X")/23 -> 0.17391304
A6: Garmin | D6: X | F6: X | I6: X | J6: X | Y6: =COUNTIF(B6:X6,"=X") -> 4 | Z6: =COUNTIF(B6:X6,"=X")/23 -> 0.17391304
A7: Google | L7: X | Y7: =COUNTIF(B7:X7,"=X") -> 1 | Z7: =COUNTIF(B7:X7,"=X")/23 -> 0.043478261
A8: Letterboxd | J8: X | L8: X | Y8: =COUNTIF(B8:X8,"=X") -> 2 | Z8: =COUNTIF(B8:X8,"=X")/23 -> 0.086956522
A9: Netflix | D9: X | J9: X | Y9: =COUNTIF(B9:X9,"=X") -> 2 | Z9: =COUNTIF(B9:X9,"=X")/23 -> 0.086956522
A10: NYT Games | D10: X | J10: X | L10: X | Y10: =COUNTIF(B10:X10,"=X") -> 3 | Z10: =COUNTIF(B10:X10,"=X")/23 -> 0.13043478
A11: Oura | B11: X | J11: X | L11: X | N11: X | Y11: =COUNTIF(B11:X11,"=X") -> 4 | Z11: =COUNTIF(B11:X11,"=X")/23 -> 0.17391304
A12: Pocket Casts | J12: X | L12: X | N12: X | Y12: =COUNTIF(B12:X12,"=X") -> 3 | Z12: =COUNTIF(B12:X12,"=X")/23 -> 0.13043478
A13: Spotify | J13: X | L13: X | Y13: =COUNTIF(B13:X13,"=X") -> 2 | Z13: =COUNTIF(B13:X13,"=X")/23 -> 0.086956522
A14: Strava | J14: X | Y14: =COUNTIF(B14:X14,"=X") -> 1 | Z14: =COUNTIF(B14:X14,"=X")/23 -> 0.043478261
A15: Tinder | J15: X | Y15: =COUNTIF(B15:X15,"=X") -> 1 | Z15: =COUNTIF(B15:X15,"=X")/23 -> 0.043478261
A16: Tiktok | J16: X | L16: X | Y16: =COUNTIF(B16:X16,"=X") -> 2 | Z16: =COUNTIF(B16:X16,"=X")/23 -> 0.086956522
A17: UDisc | J17: X | Y17: =COUNTIF(B17:X17,"=X") -> 1 | Z17: =COUNTIF(B17:X17,"=X")/23 -> 0.043478261
A18: Wikipedia | G18: X | J18: X | O18: X | Y18: =COUNTIF(B18:X18,"=X") -> 3 | Z18: =COUNTIF(B18:X18,"=X")/23 -> 0.13043478
A19: Youtube | J19: X | L19: X | Y19: =COUNTIF(B19:X19,"=X") -> 2 | Z19: =COUNTIF(B19:X19,"=X")/23 -> 0.086956522
A20: Dead By Daylight | J20: X | Y20: =COUNTIF(B20:X20,"=X") -> 1 | Z20: =COUNTIF(B20:X20,"=X")/23 -> 0.043478261
A21: eBird | E21: X | H21: X | J21: X | L21: X | S21: X | Y21: =COUNTIF(B21:X21,"=X") -> 5 | Z21: =COUNTIF(B21:X21,"=X")/23 -> 0.2173913
A22: Chess | J22: X | L22: X | N22: X | Y22: =COUNTIF(B22:X22,"=X") -> 3 | Z22: =COUNTIF(B22:X22,"=X")/23 -> 0.13043478
A23: Games Industry | L23: X | N23: X | T23: X | Y23: =COUNTIF(B23:X23,"=X") -> 3 | Z23: =COUNTIF(B23:X23,"=X")/23 -> 0.13043478
A24: Epic Games | G24: X | J24: X | L24: X | U24: X | Y24: =COUNTIF(B24:X24,"=X") -> 4 | Z24: =COUNTIF(B24:X24,"=X")/23 -> 0.17391304
A25: Collector Daily | J25: X | N25: X | Y25: =COUNTIF(B25:X25,"=X") -> 2 | Z25: =COUNTIF(B25:X25,"=X")/23 -> 0.086956522
A26: Stack Overflow | B26: X | J26: X | N26: X | R26: X | V26: X | W26: X | Y26: =COUNTIF(B26:X26,"=X") -> 6 | Z26: =COUNTIF(B26:X26,"=X")/23 -> 0.26086957
A27: Statsig | B27: X | F27: X | J27: X | Y27: =COUNTIF(B27:X27,"=X") -> 3 | Z27: =COUNTIF(B27:X27,"=X")/23 -> 0.13043478
B28: =COUNTIF(B2:B27,"=X") -> 4 | C28: =COUNTIF(C2:C27,"=X") -> 1 | D28: =COUNTIF(D2:D27,"=X") -> 5 | E28: =COUNTIF(E2:E27,"=X") -> 3 | F28: =COUNTIF(F2:F27,"=X") -> 2 | G28: =COUNTIF(G2:G27,"=X") -> 2 | H28: =COUNTIF(H2:H27,"=X") -> 3 | I28: =COUNTIF(I2:I27,"=X") -> 2 | ... X28: =COUNTIF(X2:X27,"=X") -> 1
B29: =COUNTIF(B2:B27,"=X")/26 -> 0.15384615 | C29: =COUNTIF(C2:C27,"=X")/26 -> 0.038461538 | D29: =COUNTIF(D2:D27,"=X")/26 -> 0.19230769 | E29: =COUNTIF(E2:E27,"=X")/26 -> 0.11538462 | F29: =COUNTIF(F2:F27,"=X")/26 -> 0.076923077 | G29: =COUNTIF(G2:G27,"=X")/26 -> 0.076923077 | H29: =COUNTIF(H2:H27,"=X")/26 -> 0.11538462 | I29: =COUNTIF(I2:I27,"=X")/26 -> 0.076923077 | ... X29: =COUNTIF(X2:X27,"=X")/26 -> 0.038461538
A33: Name of Provider | B33: Area | C33: Bar | D33: Circle | E33: Diagram | F33: Distribution | G33: Grid & Matrix | H33: Line | I33: Map | J33: Point | K33: Table | L33: Text | M33: Trees & Networks
A34: Backblaze | B34: =IF(COUNTA(M2)>0,"X","") | C34: =IF(COUNTA(C2,E2,G2,R2,S2,V2)>0,"X","") | D34: =IF(COUNTA(K2,T2)>0,"X","") -> X | E34: =IF(COUNTA(O2,W2)>0,"X","") | F34: =IF(COUNTA(G2)>0,"X","") | H34: =IF(COUNTA(H2,I2)>0,"X","") -> X | I34: =IF(COUNTA(E2,S2)>0,"X","") | J34: =IF(COUNTA(C2,V2,X2)>0,"X","") | K34: =IF(COUNTA(N2,L2,J2)>0,"X","") -> X | M34: =IF(COUNTA(P2)>0,"X","") | N34: =COUNTIF(B34:M34,"=X") -> 3 | O34: =COUNTIF(B34:M34,"=X")/12 -> 0.25 | Q34: Based on visualization taxonomy:
A35: Cloudflare | B35: =IF(COUNTA(M3)>0,"X","") -> X | C35: =IF(COUNTA(C3,E3,G3,R3,S3,V3)>0,"X","") -> X | D35: =IF(COUNTA(D3,F3,H3,S3,T3,W3)>0,"X","") -> X | E35: =IF(COUNTA(O3,W3)>0,"X","") | F35: =IF(COUNTA(G3)>0,"X","") | H35: =IF(COUNTA(H3,I3)>0,"X","") -> X | I35: =IF(COUNTA(E3,S3)>0,"X","") -> X | J35: =IF(COUNTA(C3,V3,X3)>0,"X","") -> X | K35: =IF(COUNTA(N3,L3,J3)>0,"X","") -> X | M35: =IF(COUNTA(P3)>0,"X","") -> X | N35: =COUNTIF(B35:M35,"=X") -> 8 | O35: =COUNTIF(B35:M35,"=X")/12 -> 0.66666667 | Q35: http://olivalab.mit.edu/Papers/Borkin_etal_MemorableVisualization_TVCG2013.pdf
A36: Duolingo | B36: =IF(COUNTA(M4)>0,"X","") | C36: =IF(COUNTA(C4,E4,G4,R4,S4,V4)>0,"X","") -> X | D36: =IF(COUNTA(K4,T4)>0,"X","") | E36: =IF(COUNTA(O4,W4)>0,"X","") | F36: =IF(COUNTA(G4)>0,"X","") | H36: =IF(COUNTA(H4,I4)>0,"X","") | I36: =IF(COUNTA(E4,S4)>0,"X","") -> X | J36: =IF(COUNTA(C4,V4,X4)>0,"X","") | K36: =IF(COUNTA(N4,L4,J4)>0,"X","") -> X | M36: =IF(COUNTA(P4)>0,"X","") | N36: =COUNTIF(B36:M36,"=X") -> 3 | O36: =COUNTIF(B36:M36,"=X")/12 -> 0.25
A37: Eight Sleep | B37: =IF(COUNTA(M5)>0,"X","") | C37: =IF(COUNTA(C5,E5,G5,R5,S5,V5)>0,"X","") | D37: =IF(COUNTA(K5,T5)>0,"X","") | E37: =IF(COUNTA(O5,W5)>0,"X","") | F37: =IF(COUNTA(G5)>0,"X","") | H37: =IF(COUNTA(H5,I5)>0,"X","") | I37: =IF(COUNTA(E5,S5)>0,"X","") | J37: =IF(COUNTA(C5,V5,X5)>0,"X","") | K37: =IF(COUNTA(N5,L5,J5)>0,"X","") -> X | M37: =IF(COUNTA(P5)>0,"X","") | N37: =COUNTIF(B37:M37,"=X") -> 1 | O37: =COUNTIF(B37:M37,"=X")/12 -> 0.083333333 | Q37: {=TRANSPOSE(B33:M33)} -> Area | R37: Stacked Area Chart
A38: Garmin | B38: =IF(COUNTA(M6)>0,"X","") | C38: =IF(COUNTA(C6,E6,G6,R6,S6,V6)>0,"X","") | D38: =IF(COUNTA(K6,T6)>0,"X","") | E38: =IF(COUNTA(O6,W6)>0,"X","") | F38: =IF(COUNTA(G6)>0,"X","") | H38: =IF(COUNTA(H6,I6)>0,"X","") -> X | I38: =IF(COUNTA(E6,S6)>0,"X","") | J38: =IF(COUNTA(C6,V6,X6)>0,"X","") | K38: =IF(COUNTA(N6,L6,J6)>0,"X","") -> X | M38: =IF(COUNTA(P6)>0,"X","") | N38: =COUNTIF(B38:M38,"=X") -> 2 | O38: =COUNTIF(B38:M38,"=X")/12 -> 0.16666667 | Q38: Bar | R38: Bar Chart (H) | S38: Column Chart (V) | T38: Grouped Bar Chart | U38: Stacked Bar Chart | V38: Stacked Prop. Bar Chart | W38: Radial Chart
A39: Google | B39: =IF(COUNTA(M7)>0,"X","") | C39: =IF(COUNTA(C7,E7,G7,R7,S7,V7)>0,"X","") | D39: =IF(COUNTA(K7,T7)>0,"X","") | E39: =IF(COUNTA(O7,W7)>0,"X","") | F39: =IF(COUNTA(G7)>0,"X","") | H39: =IF(COUNTA(H7,I7)>0,"X","") | I39: =IF(COUNTA(E7,S7)>0,"X","") | J39: =IF(COUNTA(C7,V7,X7)>0,"X","") | K39: =IF(COUNTA(N7,L7,J7)>0,"X","") -> X | M39: =IF(COUNTA(P7)>0,"X","") | N39: =COUNTIF(B39:M39,"=X") -> 1 | O39: =COUNTIF(B39:M39,"=X")/12 -> 0.083333333 | Q39: Circle | R39: Pie Chart | S39: Donut Chart
A40: Letterboxd | B40: =IF(COUNTA(M8)>0,"X","") | C40: =IF(COUNTA(C8,E8,G8,R8,S8,V8)>0,"X","") | D40: =IF(COUNTA(K8,T8)>0,"X","") | E40: =IF(COUNTA(O8,W8)>0,"X","") | F40: =IF(COUNTA(G8)>0,"X","") | H40: =IF(COUNTA(H8,I8)>0,"X","") | I40: =IF(COUNTA(E8,S8)>0,"X","") | J40: =IF(COUNTA(C8,V8,X8)>0,"X","") | K40: =IF(COUNTA(N8,L8,J8)>0,"X","") -> X | M40: =IF(COUNTA(P8)>0,"X","") | N40: =COUNTIF(B40:M40,"=X") -> 1 | O40: =COUNTIF(B40:M40,"=X")/12 -> 0.083333333 | Q40: Diagram | R40: Timeline | S40: Sankey Diagram
A41: Netflix | B41: =IF(COUNTA(M9)>0,"X","") | C41: =IF(COUNTA(C9,E9,G9,R9,S9,V9)>0,"X","") | D41: =IF(COUNTA(K9,T9)>0,"X","") | E41: =IF(COUNTA(O9,W9)>0,"X","") | F41: =IF(COUNTA(G9)>0,"X","") | H41: =IF(COUNTA(H9,I9)>0,"X","") | I41: =IF(COUNTA(E9,S9)>0,"X","") | J41: =IF(COUNTA(C9,V9,X9)>0,"X","") | K41: =IF(COUNTA(N9,L9,J9)>0,"X","") -> X | M41: =IF(COUNTA(P9)>0,"X","") | N41: =COUNTIF(B41:M41,"=X") -> 1 | O41: =COUNTIF(B41:M41,"=X")/12 -> 0.083333333 | Q41: Distribution | R41: Icon Array
A42: NYT Games | B42: =IF(COUNTA(M10)>0,"X","") | C42: =IF(COUNTA(C10,E10,G10,R10,S10,V10)>0,"X","") | D42: =IF(COUNTA(K10,T10)>0,"X","") | E42: =IF(COUNTA(O10,W10)>0,"X","") | F42: =IF(COUNTA(G10)>0,"X","") | H42: =IF(COUNTA(H10,I10)>0,"X","") | I42: =IF(COUNTA(E10,S10)>0,"X","") | J42: =IF(COUNTA(C10,V10,X10)>0,"X","") | K42: =IF(COUNTA(N10,L10,J10)>0,"X","") -> X | M42: =IF(COUNTA(P10)>0,"X","") | N42: =COUNTIF(B42:M42,"=X") -> 1 | O42: =COUNTIF(B42:M42,"=X")/12 -> 0.083333333 | Q42: Grid & Matrix
A43: Oura | B43: =IF(COUNTA(M11)>0,"X","") | C43: =IF(COUNTA(C11,E11,G11,R11,S11,V11)>0,"X","") | D43: =IF(COUNTA(K11,T11)>0,"X","") | E43: =IF(COUNTA(O11,W11)>0,"X","") | F43: =IF(COUNTA(G11)>0,"X","") | H43: =IF(COUNTA(H11,I11)>0,"X","") | I43: =IF(COUNTA(E11,S11)>0,"X","") | J43: =IF(COUNTA(C11,V11,X11)>0,"X","") | K43: =IF(COUNTA(N11,L11,J11)>0,"X","") -> X | M43: =IF(COUNTA(P11)>0,"X","") | N43: =COUNTIF(B43:M43,"=X") -> 1 | O43: =COUNTIF(B43:M43,"=X")/12 -> 0.083333333 | Q43: Line | R43: Line Chart | S43: Multi-Series Line Chart
...

Sheet Comparison
A1: Name of Provider | B1: Bar Chart (H) | C1: Bubble Map | D1: Column Chart (V) | E1: Choropleth Map | F1: Grouped Bar Chart | G1: Icon Array | H1: Line Chart | I1: Multi-Series Line Chart | J1: Numeric | K1: Pie Chart | L1: Ranked List | M1: Stacked Area Chart | N1: Table | O1: Timeline | P1: Tree Map
A2: Backblaze | B2: =IF(Patrickv2!B2 = Whilev2!B2,"","X") | C2: =IF(Patrickv2!C2 = Whilev2!C2,"","X") | D2: =IF(Patrickv2!D2 = Whilev2!D2,"","X") | E2: =IF(Patrickv2!E2 = Whilev2!E2,"","X") | F2: =IF(Patrickv2!F2 = Whilev2!F2,"","X") | G2: =IF(Patrickv2!G2 = Whilev2!G2,"","X") | H2: =IF(Patrickv2!H2 = Whilev2!H2,"","X") | I2: =IF(Patrickv2!I2 = Whilev2!I2,"","X") | ... P2: =IF(Patrickv2!P2 = Whilev2!P2,"","X")
A3: Cloudflare | B3: =IF(Patrickv2!B3 = Whilev2!B3,"","X") | C3: =IF(Patrickv2!C3 = Whilev2!C3,"","X") | D3: =IF(Patrickv2!D3 = Whilev2!D3,"","X") | E3: =IF(Patrickv2!E3 = Whilev2!E3,"","X") | F3: =IF(Patrickv2!F3 = Whilev2!F3,"","X") | G3: =IF(Patrickv2!G3 = Whilev2!G3,"","X") | H3: =IF(Patrickv2!H3 = Whilev2!H3,"","X") | I3: =IF(Patrickv2!I3 = Whilev2!I3,"","X") | ... P3: =IF(Patrickv2!P3 = Whilev2!P3,"","X")
A4: Duolingo | B4: =IF(Patrickv2!B4 = Whilev2!B4,"","X") | C4: =IF(Patrickv2!C4 = Whilev2!C4,"","X") | D4: =IF(Patrickv2!D4 = Whilev2!D4,"","X") | E4: =IF(Patrickv2!E4 = Whilev2!E4,"","X") | F4: =IF(Patrickv2!F4 = Whilev2!F4,"","X") | G4: =IF(Patrickv2!G4 = Whilev2!G4,"","X") | H4: =IF(Patrickv2!H4 = Whilev2!H4,"","X") | I4: =IF(Patrickv2!I4 = Whilev2!I4,"","X") | ... P4: =IF(Patrickv2!P4 = Whilev2!P4,"","X")
A5: Eight Sleep | B5: =IF(Patrickv2!B5 = Whilev2!B5,"","X") | C5: =IF(Patrickv2!C5 = Whilev2!C5,"","X") | D5: =IF(Patrickv2!D5 = Whilev2!D5,"","X") | E5: =IF(Patrickv2!E5 = Whilev2!E5,"","X") | F5: =IF(Patrickv2!F5 = Whilev2!F5,"","X") | G5: =IF(Patrickv2!G5 = Whilev2!G5,"","X") | H5: =IF(Patrickv2!H5 = Whilev2!H5,"","X") | I5: =IF(Patrickv2!I5 = Whilev2!I5,"","X") | ... P5: =IF(Patrickv2!P5 = Whilev2!P5,"","X")
A6: Garmin | B6: =IF(Patrickv2!B6 = Whilev2!B6,"","X") | C6: =IF(Patrickv2!C6 = Whilev2!C6,"","X") | D6: =IF(Patrickv2!D6 = Whilev2!D6,"","X") | E6: =IF(Patrickv2!E6 = Whilev2!E6,"","X") | F6: =IF(Patrickv2!F6 = Whilev2!F6,"","X") | G6: =IF(Patrickv2!G6 = Whilev2!G6,"","X") | H6: =IF(Patrickv2!H6 = Whilev2!H6,"","X") | I6: =IF(Patrickv2!I6 = Whilev2!I6,"","X") | ... P6: =IF(Patrickv2!P6 = Whilev2!P6,"","X")
A7: Google | B7: =IF(Patrickv2!B7 = Whilev2!B7,"","X") | C7: =IF(Patrickv2!C7 = Whilev2!C7,"","X") | D7: =IF(Patrickv2!D7 = Whilev2!D7,"","X") | E7: =IF(Patrickv2!E7 = Whilev2!E7,"","X") | F7: =IF(Patrickv2!F7 = Whilev2!F7,"","X") | G7: =IF(Patrickv2!G7 = Whilev2!G7,"","X") | H7: =IF(Patrickv2!H7 = Whilev2!H7,"","X") | I7: =IF(Patrickv2!I7 = Whilev2!I7,"","X") | ... P7: =IF(Patrickv2!P7 = Whilev2!P7,"","X")
A8: Letterboxd | B8: =IF(Patrickv2!B8 = Whilev2!B8,"","X") | C8: =IF(Patrickv2!C8 = Whilev2!C8,"","X") | D8: =IF(Patrickv2!D8 = Whilev2!D8,"","X") | E8: =IF(Patrickv2!E8 = Whilev2!E8,"","X") | F8: =IF(Patrickv2!F8 = Whilev2!F8,"","X") | G8: =IF(Patrickv2!G8 = Whilev2!G8,"","X") | H8: =IF(Patrickv2!H8 = Whilev2!H8,"","X") | I8: =IF(Patrickv2!I8 = Whilev2!I8,"","X") | ... P8: =IF(Patrickv2!P8 = Whilev2!P8,"","X")
A9: Netflix | B9: =IF(Patrickv2!B9 = Whilev2!B9,"","X") | C9: =IF(Patrickv2!C9 = Whilev2!C9,"","X") | D9: =IF(Patrickv2!D9 = Whilev2!D9,"","X") | E9: =IF(Patrickv2!E9 = Whilev2!E9,"","X") | F9: =IF(Patrickv2!F9 = Whilev2!F9,"","X") | G9: =IF(Patrickv2!G9 = Whilev2!G9,"","X") | H9: =IF(Patrickv2!H9 = Whilev2!H9,"","X") | I9: =IF(Patrickv2!I9 = Whilev2!I9,"","X") | ... P9: =IF(Patrickv2!P9 = Whilev2!P9,"","X")
A10: NYT Games | B10: =IF(Patrickv2!B10 = Whilev2!B10,"","X") | C10: =IF(Patrickv2!C10 = Whilev2!C10,"","X") | D10: =IF(Patrickv2!D10 = Whilev2!D10,"","X") | E10: =IF(Patrickv2!E10 = Whilev2!E10,"","X") | F10: =IF(Patrickv2!F10 = Whilev2!F10,"","X") | G10: =IF(Patrickv2!G10 = Whilev2!G10,"","X") | H10: =IF(Patrickv2!H10 = Whilev2!H10,"","X") | I10: =IF(Patrickv2!I10 = Whilev2!I10,"","X") | ... P10: =IF(Patrickv2!P10 = Whilev2!P10,"","X")
A11: Oura | B11: =IF(Patrickv2!B11 = Whilev2!B11,"","X") | C11: =IF(Patrickv2!C11 = Whilev2!C11,"","X") | D11: =IF(Patrickv2!D11 = Whilev2!D11,"","X") | E11: =IF(Patrickv2!E11 = Whilev2!E11,"","X") | F11: =IF(Patrickv2!F11 = Whilev2!F11,"","X") | G11: =IF(Patrickv2!G11 = Whilev2!G11,"","X") | H11: =IF(Patrickv2!H11 = Whilev2!H11,"","X") | I11: =IF(Patrickv2!I11 = Whilev2!I11,"","X") | ... P11: =IF(Patrickv2!P11 = Whilev2!P11,"","X")
A12: Pocket Casts | B12: =IF(Patrickv2!B12 = Whilev2!B12,"","X") | C12: =IF(Patrickv2!C12 = Whilev2!C12,"","X") | D12: =IF(Patrickv2!D12 = Whilev2!D12,"","X") | E12: =IF(Patrickv2!E12 = Whilev2!E12,"","X") | F12: =IF(Patrickv2!F12 = Whilev2!F12,"","X") | G12: =IF(Patrickv2!G12 = Whilev2!G12,"","X") | H12: =IF(Patrickv2!H12 = Whilev2!H12,"","X") | I12: =IF(Patrickv2!I12 = Whilev2!I12,"","X") | ... P12: =IF(Patrickv2!P12 = Whilev2!P12,"","X")
A13: Spotify | B13: =IF(Patrickv2!B13 = Whilev2!B13,"","X") | C13: =IF(Patrickv2!C13 = Whilev2!C13,"","X") | D13: =IF(Patrickv2!D13 = Whilev2!D13,"","X") | E13: =IF(Patrickv2!E13 = Whilev2!E13,"","X") | F13: =IF(Patrickv2!F13 = Whilev2!F13,"","X") | G13: =IF(Patrickv2!G13 = Whilev2!G13,"","X") | H13: =IF(Patrickv2!H13 = Whilev2!H13,"","X") | I13: =IF(Patrickv2!I13 = Whilev2!I13,"","X") | ... P13: =IF(Patrickv2!P13 = Whilev2!P13,"","X")
... A27: Statsig | B27: =IF(Patrickv2!B27 = Whilev2!B27,"","X") | C27: =IF(Patrickv2!C27 = Whilev2!C27,"","X") | D27: =IF(Patrickv2!D27 = Whilev2!D27,"","X") | E27: =IF(Patrickv2!E27 = Whilev2!E27,"","X") | F27: =IF(Patrickv2!F27 = Whilev2!F27,"","X") | G27: =IF(Patrickv2!G27 = Whilev2!G27,"","X") | H27: =IF(Patrickv2!H27 = Whilev2!H27,"","X") | I27: =IF(Patrickv2!I27 = Whilev2!I27,"","X") | ... P27: =IF(Patrickv2!P27 = Whilev2!P27,"","X")

Sheet Patrickv2
A1: Name of Provider | B1: Bar Chart (H) | C1: Bubble Map | D1: Column Chart (V) | E1: Choropleth Map | F1: Grouped Bar Chart | G1: Icon Array | H1: Line Chart | I1: Multi-Series Line Chart | J1: Numeric | K1: Pie Chart | L1: Ranked List | M1: Stacked Area Chart | N1: Table | O1: Timeline | P1: Tree Map | Q1: Sankey Chart | R1: Dumbell Chart
A2: Backblaze | D2: X | H2: X | J2: X | K2: X | N2: X
A3: Cloudflare | B3: X | C3: X | E3: X | H3: X | I3: X | J3: X | L3: X | M3: X | N3: X | P3: X
A4: Duolingo | E4: X | J4: X | L4: X | N4: X
A5: Eight Sleep | D5: X | J5: X | L5: X | N5: X
A6: Garmin | D6: X | F6: X | I6: X | J6: X
A7: Google | L7: X
A8: Letterboxd | J8: X | L8: X
A9: Netflix | D9: X | J9: X
A10: NYT Games | D10: X | J10: X | L10: X
A11: Oura | B11: X | J11: X | L11: X | N11: X
A12: Pocket Casts | J12: X | L12: X | N12: X
A13: Spotify | J13: X | L13: X
A14: Strava | J14: X
A15: Tinder | J15: X
A16: Tiktok | J16: X | L16: X
A17: UDisc | J17: X
A18: Wikipedia | G18: X | J18: X | O18: X
A19: Youtube | J19: X | L19: X
A20: Dead By Daylight | J20: X
A21: eBird | E21: X | H21: X | J21: X | L21: X
A22: Chess | J22: X | L22: X | N22: X
A23: Games Industry | L23: X | N23: X
A24: Epic Games | G24: X | J24: X | L24: X
A25: Collector Daily | J25: X | N25: X
A26: Stack Overflow | B26: X | J26: X | N26: X | Q26: X | R26: X
A27: Statsig | B27: X | F27: X | J27: X

Sheet Whilev2
A1: Name of Provider | B1: Bar Chart (H) | C1: Bubble Map | D1: Column Chart (V) | E1: Choropleth Map | F1: Grouped Bar Chart | G1: Icon Array | H1: Line Chart | I1: Multi-Series Line Chart | J1: Numeric | K1: Pie Chart | L1: Ranked List | M1: Stacked Area Chart | N1: Table | O1: Timeline | P1: Tree Map | Q1: Stacked Bar Chart | R1: Stack Prop. Bar Chart | S1: Map | T1: Donut Chart | U1: Radial Chart | V1: Dumbell Chart | W1: Sankey Diagram | X1: Dot Plot
A2: Backblaze | D2: X | H2: X | J2: X | K2: X | N2: X
A3: Cloudflare | B3: X | C3: X | E3: X | H3: X | I3: X | J3: X | L3: X | M3: X | N3: X | P3: X | Q3: X | X3: X
A4: Duolingo | E4: X | J4: X | L4: X | N4: X
A5: Eight Sleep | D5: X | J5: X | L5: X | N5: X
A6: Garmin | D6: X | F6: X | I6: X | J6: X
A7: Google | L7: X
A8: Letterboxd | J8: X | L8: X
A9: Netflix | D9: X | J9: X
A10: NYT Games | D10: X | J10: X | L10: X
A11: Oura | B11: X | J11: X | L11: X | N11: X
A12: Pocket Casts | J12: X | L12: X | N12: X
A13: Spotify | J13: X | L13: X
A14: Strava | J14: X
A15: Tinder | J15: X
A16: Tiktok | J16: X | L16: X
A17: UDisc | J17: X
A18: Wikipedia | G18: X | J18: X | O18: X
A19: Youtube | J19: X | L19: X
A20: Dead By Daylight | J20: X
A21: eBird | E21: X | H21: X | J21: X | L21: X | S21: X
A22: Chess | J22: X | L22: X | N22: X
A23: Games Industry | L23: X | N23: X | T23: X
A24: Epic Games | G24: X | J24: X | L24: X | U24: X
A25: Collector Daily | J25: X | N25: X
A26: Stack Overflow | B26: X | J26: X | N26: X | R26: X | V26: X | W26: X
A27: Statsig | B27: X | F27: X | J27: X

Sheet Codes v2
A1: Company | B1: Text (NO NUMBERS, ONLY DESCRIPTIONS) | C1: Numeric | D1: Pie Charts | E1: Table | F1: Line Chart | G1: Bar Chart | H1: Rankings List | I1: Choropleth | J1: Icon Array | K1: Hilbert Curve | L1: Image Array | M1: Timeline
A2: Backblaze | C2: X | D2: X | E2: X | F2: X | G2: X
A5: Name of Provider | B5: Line Chart | C5: Multi-Series Line Chart | D5: Coropleth Map | E5: Tree Map | F5: Heat Map | G5: Column Chart | H5: Bar Chart | I5: Grouped Bar Chart | J5: Pictorial Bar Chart | K5: Hilbert Curve | L5: Stacked Area Chart | M5: Pie Chart | N5: Table Chart | O5: Numeric | P5: Ranked List | Q5: Ranked List Visual | R5: Categorical Graphic (Image Array) | S5: Multi-panel Dashboard | T5: Comparison Pannel
A6: Backblaze | B6: Yes | C6: No | D6: No | E6: No | F6: No | G6: Yes | H6: No | I6: No | J6: No | K6: No | L6: No | M6: Yes | N6: Yes | O6: Yes | P6: No | Q6: No | R6: No | S6: No | T6: No
C9: look into map with circle radii

Sheet Dr. While Qual. Coding
A1: Company | B1: Text | C1: Numeric | D1: Pie Charts | E1: Table | F1: Line Chart | G1: Bar Chart | H1: Rankings List | I1: Choropleth | J1: Icon Array | K1: Hilbert Curve | L1: Image Array | M1: Timeline
A2: Backblaze | C2: X | D2: X | E2: X | F2: X | G2: X
A3: Cloudflare | F3: X | H3: X | K3: X
A4: Duolingo | C4: X | E4: X | I4: X
A5: Eight Sleep | C5: X | E5: X | G5: X | H5: X
A6: Garmin | F6: X | G6: X
A7: Google | F7: X | H7: X
A8: Letterboxd | C8: X | L8: X
A9: Netflix | B9: X | C9: X | G9: X | L9: X
A10: NYT Games | C10: X | G10: X | H10: X
A11: Oura | C11: X | E11: X | G11: X | H11: X
A12: Pocket Casts | B12: X | E12: X | H12: X | L12: X
A13: Spotify | B13: X | C13: X | H13: X
A14: Strava | B14: X | C14: X
A15: Tinder | B15: X | C15: X
A16: Tiktok | B16: X | C16: X | H16: X
A17: Twitch | B17: X
A18: UDisc | C18: X
A19: Wikipedia | C19: X | J19: X | M19: X
A20: Youtube | H20: X

Sheet Patrick Qual. Coding
A1: Name of Provider | B1: Title of the Summary (e.g., "Wrapped", "Year in Review") | C1: Notes | D1: Line Chart | E1: Multi-Series Line Chart | F1: Coropleth Map | G1: Tree Map | H1: Heat Map | I1: Column Chart | J1: Bar Chart | K1: Grouped Bar Chart | L1: Pictorial Bar Chart | M1: Hilbert Curve | N1: Stacked Area Chart | O1: Pie Chart | P1: Table Chart | Q1: Numeric | R1: Ranked List | S1: Ranked List Visual | T1: Categorical Graphic | U1: Multi-panel Dashboard | V1: Comparison Pannel | W1: Broad Link | X1: # Pages | Y1: URL to Example/Mention/Article/Documentation
A2: Amazon Music | B2: Amazon Music Recap | Y2: https://www.usatoday.com/story/entertainment/2025/12/02/2025-year-end-wrapped-recaps-guide/87567558007/
A3: Apple Books | B3: Apple Books Year in Review | Y3: https://appleinsider.com/inside/apple-services/tips/how-to-see-all-the-books-you-read-in-2025-with-apple-books
A4: Apple Music | B4: Apple Music Replay | Y4: https://techcrunch.com/2025/12/15/snapchat-rolls-out-its-end-of-year-recaps/
A5: Associated Press | B5: Associated Press Year in Review | Y5: https://www.ap.org/news-highlights/spotlights/2025/2025-year-in-review/
A6: Backblaze | D6: X | I6: X | O6: X | P6: X | Q6: X | W6: https://www.backblaze.com/blog/backblaze-drive-stats-for-2025/
A7: Carrot Weather | B7: Year in Review | Y7: https://www.howtogeek.com/services-for-an-epic-wrapped-collection/
A8: ChatGPT | B8: Your Year with ChatGPT | Y8: https://www.theverge.com/news/837280/spotify-wrapped-2025-recap-annual-best-of-data
A9: Cloudflare | C9: Most amount of visuals | D9: X | E9: X | F9: X | G9: X | H9: X | J9: X | K9: X | M9: X | N9: X | P9: X | Q9: X | W9: https://radar.cloudflare.com/year-in-review/2025
A10: Crunchyroll | B10: Crunchyroll Arc | Y10: https://www.crunchyroll.com/news/announcements/2025/12/15/crunchyroll-arc-2025-anime-year-in-review
A11: Daylio | B11: Year in Pixel | Y11: https://www.howtogeek.com/services-for-an-epic-wrapped-collection/
A12: Deezer | B12: My Deezer Year | Y12: https://techcrunch.com/2025/12/06/spotify-wrapped-2024-is-almost-here-its-time-to-explore-all-the-copycats/
A13: Discord | B13: Discord Checkpoint | Y13: https://www.theverge.com/news/837280/spotify-wrapped-2025-recap-annual-best-of-data
A14: Dunkin | B14: Dunkin Year in Review | Y14: https://www.businessinsider.com/spotify-linkedin-youtube-partiful-straval-recaps-2025-12
A15: Duolingo | B15: Duolingo Year in Review | F15: X | H15: X | P15: X | S15: X | W15: Example | Y15: https://people.com/uber-launches-youber-2025-a-personalized-year-in-review-exclusive-11868051
A16: Eight Sleep | B16: Year in Sleep Review | J16: X | P16: X | Q16: X | S16: X | T16: X | W16: Example | Y16: https://techcrunch.com/2025/12/06/spotify-wrapped-2024-is-almost-here-its-time-to-explore-all-the-copycats/
A17: Garmin | B17: Year in Review | E17: X | J17: X | K17: X | Q17: X | W17: https://www.garmin.com/en-US/blog/general/2025-garmin-connect-data-report/ | Y17: https://lifehacker.com/health/garmin-year-in-review-connect-plus-feature
A18: Goodreads | B18: Year in Books | Y18: https://www.goodreads.com/blog/show/3064-get-ready-for-year-in-books-2025
A19: Google | U19: X | W19: https://trends.withgoogle.com/year-in-search/2025/us/
A20: Google Photos | B20: 2025 Recap | Y20: https://blog.google/products-and-platforms/products/photos/google-photos-2025-recap/
A21: Hevy | B21: Hevy Year in Review | Y21: https://techcrunch.com/2025/12/06/spotify-wrapped-2024-is-almost-here-its-time-to-explore-all-the-copycats/
A22: Hulu | B22: Year in Review | Y22: https://techcrunch.com/2025/12/06/spotify-wrapped-2024-is-almost-here-its-time-to-explore-all-the-copycats/
A23: Instacart | B23: Year In Review | Y23: https://www.reddit.com/r/crowbro/comments/1hd1pvt/did_you_know_instacart_does_a_yearly_wrapup_guess/
A24: last.fm | B24: Playback | Y24: https://www.last.fm/user/alex_ferguson/listening-report/year/2025
A25: Kindle | B25: Kindle Unlimited Year Yearbook | Y25: https://www.facebook.com/groups/LitRPG.books/posts/25880895524840439/
A26: Letterboxd | B26: Letterboxd Year in Review | Q26: X | S26: X | T26: X | W26: Example | Y26: https://letterboxd.com/journal/2025-letterboxd-year-in-review-faq/
A27: LinkedIn | B27: LinkedIn Year in Review | Y27: https://www.businessinsider.com/spotify-linkedin-youtube-partiful-straval-recaps-2025-12
A28: Monzo | B28: Year in Monzo | Y28: https://mashable.com/article/monzo-wrapped-end-of-year
A29: MyAnimeList | B29: MAL Wrap-Up | Y29: https://myanimelist.net/forum/?topicid=2247124
A30: Netflix | Q30: X | S30: X | T30: X | W30: https://about.netflix.com/en/news/what-we-watched-the-second-half-of-2025
A31: Nintendo | B31: Nintendo Switch Year in Review | Y31: https://www.theverge.com/news/837280/spotify-wrapped-2025-recap-annual-best-of-data
A32: NYT Games | B32: Year in Games | J32: X | Q32: X | R32: X | T32: X | W32: Example | Y32: https://www.theverge.com/news/837280/spotify-wrapped-2025-recap-annual-best-of-data
A33: Oura | B33: Year in Review | F33: X | I33: X | R33: X | V33: X | W33: Example | Y33: https://ouraring.com/blog/2025-year-in-review/
A34: Pandora | B34: Pandora Year in Review | Y34: https://techcrunch.com/2025/12/06/spotify-wrapped-2024-is-almost-here-its-time-to-explore-all-the-copycats/
A35: Partiful | B35: Partiful After Party | Y35: https://www.businessinsider.com/spotify-linkedin-youtube-partiful-straval-recaps-2025-12
A36: PlayStation | B36: PlayStation Wrap-Up | Y36: https://techcrunch.com/2025/12/06/spotify-wrapped-2024-is-almost-here-its-time-to-explore-all-the-copycats/
A37: Peloton | B37: Victory Lap | Y37: https://www.pelobuddy.com/year-review-victory-lap-2025/
A38: Pocket Casts | B38: Playback | Q38: X | S38: X | W38: Example | Y38: https://playback.pocketcasts.com/
A39: Reclaim | B39: Reclaim Recap | Y39: https://techcrunch.com/2025/12/06/spotify-wrapped-2024-is-almost-here-its-time-to-explore-all-the-copycats/
A40: Reddit | B40: Reddit Recap | Y40: https://www.makeuseof.com/spotify-wrapped-copycats/
...

Sheet Only Broad
A1: Name of Provider | B1: Title of the Summary (e.g., "Wrapped", "Year in Review") | C1: Broad Link | D1: # Pages | E1: URL to Example/Mention/Article/Documentation | F1: Device (Vertical / Horizontal)
A2: Amazon Music | B2: Amazon Music Recap | E2: https://www.usatoday.com/story/entertainment/2025/12/02/2025-year-end-wrapped-recaps-guide/87567558007/ | F2: Vertical
A3: Apple Books | B3: Apple Books Year in Review | E3: https://appleinsider.com/inside/apple-services/tips/how-to-see-all-the-books-you-read-in-2025-with-apple-books
A4: Apple Music | B4: Apple Music Replay | E4: https://techcrunch.com/2025/12/15/snapchat-rolls-out-its-end-of-year-recaps/ | F4: Vertical
A5: Associated Press | B5: Associated Press Year in Review | E5: https://www.ap.org/news-highlights/spotlights/2025/2025-year-in-review/ | F5: Horizontal
A6: Backblaze | C6: https://www.backblaze.com/blog/backblaze-drive-stats-for-2025/
A7: Carrot Weather | B7: Year in Review | E7: https://www.howtogeek.com/services-for-an-epic-wrapped-collection/ | F7: Vertical
A8: ChatGPT | B8: Your Year with ChatGPT | E8: https://www.theverge.com/news/837280/spotify-wrapped-2025-recap-annual-best-of-data | F8: Vertical
A9: Cloudflare | C9: https://radar.cloudflare.com/year-in-review/2025
A10: Crunchyroll | B10: Crunchyroll Arc | E10: https://www.crunchyroll.com/news/announcements/2025/12/15/crunchyroll-arc-2025-anime-year-in-review | F10: Vertical
A11: Daylio | B11: Year in Pixel | E11: https://www.howtogeek.com/services-for-an-epic-wrapped-collection/ | F11: Vertical
A12: Deezer | B12: My Deezer Year | E12: https://techcrunch.com/2025/12/06/spotify-wrapped-2024-is-almost-here-its-time-to-explore-all-the-copycats/ | F12: Vertical
A13: Discord | B13: Discord Checkpoint | E13: https://www.theverge.com/news/837280/spotify-wrapped-2025-recap-annual-best-of-data | F13: Vertical
A14: Dunkin | B14: Dunkin Year in Review | E14: https://www.businessinsider.com/spotify-linkedin-youtube-partiful-straval-recaps-2025-12 | F14: Vertical
A15: Duolingo | B15: Duolingo Year in Review | C15: Example | E15: https://people.com/uber-launches-youber-2025-a-personalized-year-in-review-exclusive-11868051 | F15: Vertical
A16: Eight Sleep | B16: Year in Sleep Review | C16: Example | E16: https://techcrunch.com/2025/12/06/spotify-wrapped-2024-is-almost-here-its-time-to-explore-all-the-copycats/ | F16: Vertical
A17: Garmin | B17: Year in Review | C17: https://www.garmin.com/en-US/blog/general/2025-garmin-connect-data-report/ | E17: https://lifehacker.com/health/garmin-year-in-review-connect-plus-feature | F17: Vertical
A18: Goodreads | B18: Year in Books | E18: https://www.goodreads.com/blog/show/3064-get-ready-for-year-in-books-2025 | F18: Vertical
A19: Google | C19: https://trends.withgoogle.com/year-in-search/2025/us/
A20: Google Photos | B20: 2025 Recap | E20: https://blog.google/products-and-platforms/products/photos/google-photos-2025-recap/ | F20: Vertical
A21: Hevy | B21: Hevy Year in Review | E21: https://techcrunch.com/2025/12/06/spotify-wrapped-2024-is-almost-here-its-time-to-explore-all-the-copycats/ | F21: Vertical
A22: Hulu | B22: Year in Review | E22: https://techcrunch.com/2025/12/06/spotify-wrapped-2024-is-almost-here-its-time-to-explore-all-the-copycats/ | F22: Horizontal
A23: Instacart | B23: Year In Review | E23: https://www.reddit.com/r/crowbro/comments/1hd1pvt/did_you_know_instacart_does_a_yearly_wrapup_guess/ | F23: Vertical
A24: last.fm | B24: Playback | E24: https://www.last.fm/user/alex_ferguson/listening-report/year/2025 | F24: Horizontal
A25: Kindle | B25: Kindle Unlimited Year Yearbook | E25: https://www.facebook.com/groups/LitRPG.books/posts/25880895524840439/
A26: Letterboxd | B26: Letterboxd Year in Review | C26: Example | E26: https://letterboxd.com/journal/2025-letterboxd-year-in-review-faq/ | F26: Vertical
A27: LinkedIn | B27: LinkedIn Year in Review | E27: https://www.businessinsider.com/spotify-linkedin-youtube-partiful-straval-recaps-2025-12 | F27: Vertical
A28: Monzo | B28: Year in Monzo | E28: https://mashable.com/article/monzo-wrapped-end-of-year | F28: Vertical
A29: MyAnimeList | B29: MAL Wrap-Up | E29: https://myanimelist.net/forum/?topicid=2247124
A30: Netflix | C30: https://about.netflix.com/en/news/what-we-watched-the-second-half-of-2025
A31: Nintendo | B31: Nintendo Switch Year in Review | E31: https://www.theverge.com/news/837280/spotify-wrapped-2025-recap-annual-best-of-data | F31: Horizontal
A32: NYT Games | B32: Year in Games | C32: Example | E32: https://www.theverge.com/news/837280/spotify-wrapped-2025-recap-annual-best-of-data | F32: Vertical
A33: Oura | B33: Year in Review | C33: Example | E33: https://ouraring.com/blog/2025-year-in-review/ | F33: Vertical
A34: Pandora | B34: Pandora Year in Review | E34: https://techcrunch.com/2025/12/06/spotify-wrapped-2024-is-almost-here-its-time-to-explore-all-the-copycats/ | F34: Vertical
A35: Partiful | B35: Partiful After Party | E35: https://www.businessinsider.com/spotify-linkedin-youtube-partiful-straval-recaps-2025-12 | F35: Vertical
A36: PlayStation | B36: PlayStation Wrap-Up | E36: https://techcrunch.com/2025/12/06/spotify-wrapped-2024-is-almost-here-its-time-to-explore-all-the-copycats/ | F36: Horizontal
A37: Peloton | B37: Victory Lap | E37: https://www.pelobuddy.com/year-review-victory-lap-2025/ | F37: Vertical
A38: Pocket Casts | B38: Playback | C38: Example | E38: https://playback.pocketcasts.com/
A39: Reclaim | B39: Reclaim Recap | E39: https://techcrunch.com/2025/12/06/spotify-wrapped-2024-is-almost-here-its-time-to-explore-all-the-copycats/ | F39: Horizontal
A40: Reddit | B40: Reddit Recap | E40: https://www.makeuseof.com/spotify-wrapped-copycats/ | F40: Vertical
...

Sheet One Provider per Row
A1: Name of Provider | B1: Title of the Summary (e.g., "Wrapped", "Year in Review") | C1: Example #1 Link | D1: Example #2 Link | E1: Personal Summary | F1: Broad Link | G1: # Pages | H1: Personalized, Broad, or Both | I1: URL to Example/Mention/Article/Documentation | J1: Device (Vertical / Horizontal)
A2: Amazon Music | B2: Amazon Music Recap | C2: Example 1 | D2: Example 2 | G2: ~20 | H2: Personalized | I2: https://www.usatoday.com/story/entertainment/2025/12/02/2025-year-end-wrapped-recaps-guide/87567558007/ | J2: Vertical
A3: Apple Books | B3: Apple Books Year in Review | C3: Example 1 | G3: ~10 | H3: Personalized | I3: https://appleinsider.com/inside/apple-services/tips/how-to-see-all-the-books-you-read-in-2025-with-apple-books
A4: Apple Music | B4: Apple Music Replay | C4: Example 1 | D4: Example 2 | G4: ~12 | H4: Personalized | I4: https://techcrunch.com/2025/12/15/snapchat-rolls-out-its-end-of-year-recaps/ | J4: Vertical
A5: BGStats | B5: Year Stats 2025 | C5: https://www.bgstatsapp.com/2025/12/11/year-stats-2025/
A6: Carrot Weather | B6: Year in Review | C6: Example 1 | D6: Example 2 | G6: 1 | H6: Personalized | I6: https://www.howtogeek.com/services-for-an-epic-wrapped-collection/ | J6: Vertical
A7: ChatGPT | B7: Your Year with ChatGPT | C7: Example 1 | D7: Example 2 | G7: ~11 | H7: Personalized | I7: https://www.theverge.com/news/837280/spotify-wrapped-2025-recap-annual-best-of-data | J7: Vertical
A8: Crunchyroll | B8: Crunchyroll Arc | C8: Example 1 | H8: Personalized | I8: https://www.crunchyroll.com/news/announcements/2025/12/15/crunchyroll-arc-2025-anime-year-in-review | J8: Vertical
A9: Daylio | B9: Year in Pixel | C9: Example 1 | D9: Example 2 | G9: 1 | H9: Personalized | I9: https://www.howtogeek.com/services-for-an-epic-wrapped-collection/ | J9: Vertical
A10: Deezer | B10: My Deezer Year | C10: Example 1 | D10: Example 2 | G10: ~15 | H10: Personalized | I10: https://techcrunch.com/2025/12/06/spotify-wrapped-2024-is-almost-here-its-time-to-explore-all-the-copycats/ | J10: Vertical
A11: Discord | B11: Discord Checkpoint | C11: Example 1 | D11: Example 2 | G11: ~9 | H11: Personalized | I11: https://www.theverge.com/news/837280/spotify-wrapped-2025-recap-annual-best-of-data | J11: Vertical
A12: Dunkin | B12: Dunkin Year in Review | C12: Example 1 | D12: Example 2 | G12: 1 | H12: Personalized | I12: https://www.businessinsider.com/spotify-linkedin-youtube-partiful-straval-recaps-2025-12 | J12: Vertical
A13: Duolingo | B13: Duolingo Year in Review | C13: Example 1 | D13: Example 2 | G13: ~8 | H13: Personalized | I13: https://people.com/uber-launches-youber-2025-a-personalized-year-in-review-exclusive-11868051 | J13: Vertical
A14: Garmin | B14: Year in Review | C14: Example 1 | G14: ~10 | H14: Personalized | I14: https://lifehacker.com/health/garmin-year-in-review-connect-plus-feature | J14: Vertical
A15: Goodreads | B15: Year in Books | C15: Example 1 | D15: Example 2 | G15: ~8 | H15: Personalized | I15: https://www.goodreads.com/blog/show/3064-get-ready-for-year-in-books-2025 | J15: Vertical
A16: Google Photos | B16: 2025 Recap | C16: Example 1 | G16: ~8 | H16: Personalized | I16: https://blog.google/products-and-platforms/products/photos/google-photos-2025-recap/ | J16: Vertical
A17: Hevy | B17: Hevy Year in Review | C17: Example 1 | D17: Example 2 | G17: ~2 | H17: Personalized | I17: https://techcrunch.com/2025/12/06/spotify-wrapped-2024-is-almost-here-its-time-to-explore-all-the-copycats/ | J17: Vertical
A18: Hulu | B18: Year in Review | C18: Example 1 | G18: ~4 | H18: Personalized | I18: https://techcrunch.com/2025/12/06/spotify-wrapped-2024-is-almost-here-its-time-to-explore-all-the-copycats/ | J18: Horizontal
A19: Instacart | B19: Year In Review | C19: Example 1 | D19: might not be real | G19: ~6 | H19: Personalized | I19: https://www.reddit.com/r/crowbro/comments/1hd1pvt/did_you_know_instacart_does_a_yearly_wrapup_guess/ | J19: Vertical
A20: last.fm | B20: Playback | C20: Example 1 | D20: Example 2 | G20: 1 | H20: Personalized | I20: https://www.last.fm/user/alex_ferguson/listening-report/year/2025 | J20: Horizontal
A21: Kindle | B21: Kindle Unlimited Year Yearbook | C21: Example 1 | G21: ~3 | H21: Personalized | I21: https://www.facebook.com/groups/LitRPG.books/posts/25880895524840439/
A22: Letterboxd | B22: Year in Film | C22: Example 1 | D22: Example 2 | G22: N/A | H22: Both | I22: https://letterboxd.com/journal/2025-letterboxd-year-in-review-faq/ | J22: Vertical
A23: LinkedIn | B23: LinkedIn Year in Review | C23: Example 1 | G23: ~6 | H23: Personalized | I23: https://www.businessinsider.com/spotify-linkedin-youtube-partiful-straval-recaps-2025-12 | J23: Vertical
A24: Monzo | B24: Year in Monzo | C24: Example 1 | G24: ~20 | H24: Personalized | I24: https://mashable.com/article/monzo-wrapped-end-of-year | J24: Vertical
A25: MyAnimeList | B25: MAL Wrap-Up | C25: Example 1 | D25: Example 2 | G25: 19 | H25: Personalized | I25: https://myanimelist.net/forum/?topicid=2247124
A26: Nintendo | B26: Nintendo Switch Year in Review | C26: Example 1 | D26: Example 2 | G26: 1 | H26: Personalized | I26: https://www.theverge.com/news/837280/spotify-wrapped-2025-recap-annual-best-of-data | J26: Horizontal
A27: NYT Games | B27: Year in Games | C27: Example 1 | D27: Example 2 | G27: N/A | H27: Both | I27: https://www.theverge.com/news/837280/spotify-wrapped-2025-recap-annual-best-of-data | J27: Vertical
A28: Oura | B28: Year in Review | C28: Example 1 | G28: ~15 | H28: Personalized | I28: https://ouraring.com/blog/2025-year-in-review/ | J28: Vertical
A29: Pandora | B29: Pandora Year in Review | C29: Example 1 | G29: 1 | H29: Personalized | I29: https://techcrunch.com/2025/12/06/spotify-wrapped-2024-is-almost-here-its-time-to-explore-all-the-copycats/ | J29: Vertical
A30: Partiful | B30: Partiful After Party | C30: Example 1 | G30: 1 | H30: Personalized | I30: https://www.businessinsider.com/spotify-linkedin-youtube-partiful-straval-recaps-2025-12 | J30: Vertical
A31: PlayStation | B31: PlayStation Wrap-Up | C31: Example 1 | D31: Example 2 | G31: ~7 | H31: Personalized | I31: https://techcrunch.com/2025/12/06/spotify-wrapped-2024-is-almost-here-its-time-to-explore-all-the-copycats/ | J31: Horizontal
A32: Peloton | B32: Victory Lap | C32: Example 1 | D32: Example 2 | G32: ~18 | H32: Personalized | I32: https://www.pelobuddy.com/year-review-victory-lap-2025/ | J32: Vertical
A33: Pocket Casts | B33: Playback | C33: Example 1 | D33: Example 2 | G33: ~10 | H33: Personalized | I33: https://playback.pocketcasts.com/
A34: Reddit | B34: Reddit Recap | C34: Example 1 | H34: Personalized | I34: https://www.makeuseof.com/spotify-wrapped-copycats/ | J34: Vertical
A35: SoundCloud | B35: SoundCloud Your Playback | C35: Example 1 | D35: Example 2 | G35: ~4 | H35: Personalized | I35: https://www.usatoday.com/story/entertainment/2025/12/02/2025-year-end-wrapped-recaps-guide/87567558007/ | J35: Vertical
A36: Spotify | B36: Spotify Wrapped | C36: Example 1 | G36: ~10 | H36: Personalized | I36: https://www.usatoday.com/story/entertainment/2025/12/02/2025-year-end-wrapped-recaps-guide/87567558007/ | J36: Vertical
A37: Starbucks | B37: Starbucks Blend - Year in Review | C37: Example 1 | G37: 1 | H37: Personalized | I37: https://www.reddit.com/r/socialmedia/comments/18cptis/what_are_some_other_services_that_offer_yearend/ | J37: Vertical
A38: Steam | B38: Steam Replay | C38: Example 1 | G38: ~1 | H38: Personalized | I38: https://www.howtogeek.com/services-for-an-epic-wrapped-collection/ | J38: Horizontal
A39: Storygraph | B39: Wrap-Up | C39: Example 1 | D39: Example 2 | G39: 1 | H39: Personalized | I39: https://www.reddit.com/r/TheStoryGraph/comments/1q0daqi/2025_wrap_up/ | J39: Vertical
A40: Strava | B40: Year in Sport | C40: Example 1 | G40: ~24 | H40: Personalized | I40: https://techcrunch.com/2025/12/06/spotify-wrapped-2024-is-almost-here-its-time-to-explore-all-the-copycats/ | J40: Vertical
...

Sheet PRE-FILTER One Provider per Row
A1: Name of Provider | B1: Title of the Summary (e.g., "Wrapped", "Year in Review") | C1: Example #1 Link | D1: Example #2 Link | E1: Personal Summary | F1: Broad Link | G1: # Pages | H1: Personalized, Broad, or Both | I1: URL to Example/Mention/Article/Documentation | J1: Device (Vertical / Horizontal)
A2: Amazon Music | B2: Amazon Music Recap | C2: Example 1 | D2: Example 2 | G2: ~20 | H2: Personalized | I2: https://www.usatoday.com/story/entertainment/2025/12/02/2025-year-end-wrapped-recaps-guide/87567558007/ | J2: Vertical
A3: Apple Books | B3: Apple Books Year in Review | C3: Example 1 | G3: ~10 | H3: Personalized | I3: https://appleinsider.com/inside/apple-services/tips/how-to-see-all-the-books-you-read-in-2025-with-apple-books
A4: Apple Music | B4: Apple Music Replay | C4: Example 1 | D4: Example 2 | G4: ~12 | H4: Personalized | I4: https://techcrunch.com/2025/12/15/snapchat-rolls-out-its-end-of-year-recaps/ | J4: Vertical
A5: Associated Press | B5: Associated Press Year in Review | C5: Example 1 | D5: Example 2 | G5: N/A | H5: Broad | I5: https://www.ap.org/news-highlights/spotlights/2025/2025-year-in-review/ | J5: Horizontal
A6: Carrot Weather | B6: Year in Review | C6: Example 1 | D6: Example 2 | G6: 1 | H6: Personalized | I6: https://www.howtogeek.com/services-for-an-epic-wrapped-collection/ | J6: Vertical
A7: ChatGPT | B7: Your Year with ChatGPT | C7: Example 1 | D7: Example 2 | G7: ~11 | H7: Personalized | I7: https://www.theverge.com/news/837280/spotify-wrapped-2025-recap-annual-best-of-data | J7: Vertical
A8: Crunchyroll | B8: Crunchyroll Arc | C8: Example 1 | H8: Personalized | I8: https://www.crunchyroll.com/news/announcements/2025/12/15/crunchyroll-arc-2025-anime-year-in-review | J8: Vertical
A9: Daylio | B9: Year in Pixel | C9: Example 1 | D9: Example 2 | G9: 1 | H9: Personalized | I9: https://www.howtogeek.com/services-for-an-epic-wrapped-collection/ | J9: Vertical
A10: Deezer | B10: My Deezer Year | C10: Example 1 | D10: Example 2 | G10: ~15 | H10: Personalized | I10: https://techcrunch.com/2025/12/06/spotify-wrapped-2024-is-almost-here-its-time-to-explore-all-the-copycats/ | J10: Vertical
A11: Discord | B11: Discord Checkpoint | C11: Example 1 | D11: Example 2 | G11: ~9 | H11: Personalized | I11: https://www.theverge.com/news/837280/spotify-wrapped-2025-recap-annual-best-of-data | J11: Vertical
A12: Dunkin | B12: Dunkin Year in Review | C12: Example 1 | D12: Example 2 | G12: 1 | H12: Personalized | I12: https://www.businessinsider.com/spotify-linkedin-youtube-partiful-straval-recaps-2025-12 | J12: Vertical
A13: Duolingo | B13: Duolingo Year in Review | C13: Example 1 | D13: Example 2 | G13: ~8 | H13: Personalized | I13: https://people.com/uber-launches-youber-2025-a-personalized-year-in-review-exclusive-11868051 | J13: Vertical
A14: Eight Sleep | B14: Year in Sleep Review | C14: Example 1 | G14: N/A | H14: Broad | I14: https://techcrunch.com/2025/12/06/spotify-wrapped-2024-is-almost-here-its-time-to-explore-all-the-copycats/ | J14: Vertical
A15: Garmin | B15: Year in Review | C15: Example 1 | G15: ~10 | H15: Personalized | I15: https://lifehacker.com/health/garmin-year-in-review-connect-plus-feature | J15: Vertical
A16: Goodreads | B16: Year in Books | C16: Example 1 | D16: Example 2 | G16: ~8 | H16: Personalized | I16: https://www.goodreads.com/blog/show/3064-get-ready-for-year-in-books-2025 | J16: Vertical
A17: Google Photos | B17: 2025 Recap | C17: Example 1 | G17: ~8 | H17: Personalized | I17: https://blog.google/products-and-platforms/products/photos/google-photos-2025-recap/ | J17: Vertical
A18: Hevy | B18: Hevy Year in Review | C18: Example 1 | D18: Example 2 | G18: ~2 | H18: Personalized | I18: https://techcrunch.com/2025/12/06/spotify-wrapped-2024-is-almost-here-its-time-to-explore-all-the-copycats/ | J18: Vertical
A19: Hulu | B19: Year in Review | C19: Example 1 | G19: ~4 | H19: Personalized | I19: https://techcrunch.com/2025/12/06/spotify-wrapped-2024-is-almost-here-its-time-to-explore-all-the-copycats/ | J19: Horizontal
A20: Instacart | B20: Year In Review | C20: Example 1 | D20: might not be real | G20: ~6 | H20: Personalized | I20: https://www.reddit.com/r/crowbro/comments/1hd1pvt/did_you_know_instacart_does_a_yearly_wrapup_guess/ | J20: Vertical
A21: last.fm | B21: Playback | C21: Example 1 | D21: Example 2 | G21: 1 | H21: Personalized | I21: https://www.last.fm/user/alex_ferguson/listening-report/year/2025 | J21: Horizontal
A22: Kindle | B22: Kindle Unlimited Year Yearbook | C22: Example 1 | G22: ~3 | H22: Personalized | I22: https://www.facebook.com/groups/LitRPG.books/posts/25880895524840439/
A23: Letterboxd | B23: Letterboxd Year in Review | C23: Example 1 | G23: N/A | H23: Broad | I23: https://letterboxd.com/journal/2025-letterboxd-year-in-review-faq/ | J23: Vertical
A24: LinkedIn | B24: LinkedIn Year in Review | C24: Example 1 | G24: ~6 | H24: Personalized | I24: https://www.businessinsider.com/spotify-linkedin-youtube-partiful-straval-recaps-2025-12 | J24: Vertical
A25: Monzo | B25: Year in Monzo | C25: Example 1 | G25: ~20 | H25: Personalized | I25: https://mashable.com/article/monzo-wrapped-end-of-year | J25: Vertical
A26: MyAnimeList | B26: MAL Wrap-Up | C26: Example 1 | D26: Example 2 | G26: 19 | H26: Personalized | I26: https://myanimelist.net/forum/?topicid=2247124
A27: Nintendo | B27: Nintendo Switch Year in Review | C27: Example 1 | D27: Example 2 | G27: 1 | H27: Personalized | I27: https://www.theverge.com/news/837280/spotify-wrapped-2025-recap-annual-best-of-data | J27: Horizontal
A28: NYT Games | B28: Year in Games | C28: Example 1 | D28: Example 2 | G28: N/A | H28: Both | I28: https://www.theverge.com/news/837280/spotify-wrapped-2025-recap-annual-best-of-data | J28: Vertical
A29: Oura | B29: Year in Review | C29: Example 1 | G29: ~15 | H29: Personalized | I29: https://ouraring.com/blog/2025-year-in-review/ | J29: Vertical
A30: Pandora | B30: Pandora Year in Review | C30: Example 1 | G30: 1 | H30: Personalized | I30: https://techcrunch.com/2025/12/06/spotify-wrapped-2024-is-almost-here-its-time-to-explore-all-the-copycats/ | J30: Vertical
A31: Partiful | B31: Partiful After Party | C31: Example 1 | G31: 1 | H31: Personalized | I31: https://www.businessinsider.com/spotify-linkedin-youtube-partiful-straval-recaps-2025-12 | J31: Vertical
A32: PlayStation | B32: PlayStation Wrap-Up | C32: Example 1 | D32: Example 2 | G32: ~7 | H32: Personalized | I32: https://techcrunch.com/2025/12/06/spotify-wrapped-2024-is-almost-here-its-time-to-explore-all-the-copycats/ | J32: Horizontal
A33: Peloton | B33: Victory Lap | C33: Example 1 | D33: Example 2 | G33: ~18 | H33: Personalized | I33: https://www.pelobuddy.com/year-review-victory-lap-2025/ | J33: Vertical
A34: Pocket Casts | B34: Playback | C34: Example 1 | D34: Example 2 | G34: ~10 | H34: Personalized | I34: https://playback.pocketcasts.com/
A35: Reclaim | B35: Reclaim Recap | C35: Cant find any | I35: https://techcrunch.com/2025/12/06/spotify-wrapped-2024-is-almost-here-its-time-to-explore-all-the-copycats/ | J35: Horizontal
A36: Reddit | B36: Reddit Recap | C36: Cant find any for this year | I36: https://www.makeuseof.com/spotify-wrapped-copycats/ | J36: Vertical
A37: SoundCloud | B37: SoundCloud Your Playback | C37: Example 1 | D37: Example 2 | G37: ~4 | H37: Personalized | I37: https://www.usatoday.com/story/entertainment/2025/12/02/2025-year-end-wrapped-recaps-guide/87567558007/ | J37: Vertical
A38: Spotify | B38: Spotify Wrapped | C38: Example 1 | G38: ~10 | H38: Personalized | I38: https://www.usatoday.com/story/entertainment/2025/12/02/2025-year-end-wrapped-recaps-guide/87567558007/ | J38: Vertical
A39: Starbucks | B39: Starbucks Blend - Year in Review | C39: Example 1 | G39: 1 | H39: Personalized | I39: https://www.reddit.com/r/socialmedia/comments/18cptis/what_are_some_other_services_that_offer_yearend/ | J39: Vertical
A40: Steam | B40: Steam Replay | C40: Example 1 | G40: ~1 | H40: Personalized | I40: https://www.howtogeek.com/services-for-an-epic-wrapped-collection/ | J40: Horizontal
...

Sheet Original Data (Aggregated)
A1: Name of Provider | B1: Provider's Name for the Summary | C1: URL to Example/Mention/Article/Documentation
A2: Spotify, Apple Music, Youtube, Amazon, Snapchat, SoundCloud | B2: Spotify Wrapped, Apple Replay, Youtube Recap, Amazon Delivered, Snapchat Recap, SoundCloud Your Playback | C2: https://www.usatoday.com/story/entertainment/2025/12/02/2025-year-end-wrapped-recaps-guide/87567558007/
A3: Spotify, Youtube, Apple, Amazon, Twitch, Duolingo | B3: Spotify Wrapped, Youtube Recap, Apple Replay, Amazon Delivered, Twitch Recap, Duolingo Year in Review | C3: https://www.usnews.com/news/business/articles/2025-12-03/how-to-find-spotify-wrapped-youtube-recap-and-more-as-2025-comes-to-a-close
A4: Youtube, LinkedIn, Spotify, Partiful, Snapchat, Dunkin | B4: Youtube Recap, LinkedIn Year in Review, Spotify Wrapped, Partiful After Party, Snapchar Recap, Dunkin Year in Review | C4: https://www.businessinsider.com/spotify-linkedin-youtube-partiful-straval-recaps-2025-12
A5: Spotify, Youtube Music, Apple Music, Instagram, Facebook, Snapchat | B5: Spotify Wrapped, Youtube Music Recap, Apple Music Replay, Instagram Playback, Facebook Year Together, Snapchat Recap | C5: https://www.popsci.com/diy/year-in-review-apps/
